<?xml version="1.0"?>
<robot xmlns:xacro="http://www.ros.org/wiki/xacro" name="dyros_mobile_wheel">

  <xacro:macro params="robot_id:='dyros_mobile_wheel' connected_to:='' xyz:='0 0 0' rpy:='0 0 0'">
    <xacro:unless value="${not connected_to}">
      <joint name="${robot_id}_joint_${connected_to}" type="fixed">
        <parent link="${connected_to}"/>
        <child link="${robot_id}_fixed_part"/>
        <origin rpy="${rpy}" xyz="${xyz}"/>
      </joint>
    </xacro:unless>

    <link name="${robot_id}_fixed_part">
    </link>

    <link name="${robot_id}_link0">
      <visual>
        <origin xyz="0 0 0" rpy="0 0 0"/>
        <geometry>
          <mesh filename="package://dyros_mobile_model/model/meshes/wheel_body.stl"/>
        </geometry>
      </visual>
      <collision>
        <origin xyz="0 0 0" rpy="0 0 0"/>
        <geometry>
          <cylinder length="0.2" radius="0.1"/>
        </geometry>
      </collision>
    </link>

    <joint name="${robot_id}_joint0" type="revolute">
      <parent link="${robot_id}_fixed_part"/>
      <child link="${robot_id}_link0"/>
      <origin xyz="0 0 0" rpy="0 0 0"/>
      <axis xyz="0 0 1"/>
      <limit effort="1000000" velocity="1000000"/>
      <!-- <safety_controller k_position="100.0" k_velocity="40.0" soft_lower_limit="-2.8973" soft_upper_limit="2.8973"/> -->
    </joint>


    <link name="${robot_id}_link1">
      <visual>
        <origin xyz="0 0 0" rpy="-${pi/2} 0 0"/>
        <geometry>
          <mesh filename="package://dyros_mobile_model/model/meshes/wheel_rotate.stl"/>
        </geometry>
      </visual>
      <collision>
        <origin xyz="0 0 0" rpy="0 0 0"/>
        <geometry>
          <cylinder length="0.05" radius="0.2"/>
        </geometry>
      </collision>
    </link>

    <joint name="${robot_id}_joint1" type="revolute">
      <parent link="${robot_id}_link0"/>
      <child link="${robot_id}_link1"/>
      <origin xyz="-0.02 0 -0.052" rpy="${pi/2} 0 0"/>
      <axis xyz="0 0 1"/>
      <limit effort="1000000" velocity="1000000"/>
      <!-- <safety_controller k_position="100.0" k_velocity="40.0" soft_lower_limit="-2.8973" soft_upper_limit="2.8973"/> -->
    </joint>
  </xacro:macro>
</robot>